Workbook
Name TitleRegion1.A6.E63.1: #REF!
Name TitleRegion1.A6.E63.10: #REF!
Name TitleRegion1.A6.E63.11: #REF!
Name TitleRegion1.A6.E63.12: #REF!
Name TitleRegion1.A6.E63.13: #REF!
Name TitleRegion1.A6.E63.2: #REF!
Name TitleRegion1.A6.E63.3: #REF!
Name TitleRegion1.A6.E63.4: 'January-2018'!$A$7:$A$7
Name TitleRegion1.A6.E63.5: 'February-2018'!$A$7:$A$7
Name TitleRegion1.A6.E63.6: 'March-2018'!$A$7:$A$7
Name TitleRegion1.A6.E63.7: #REF!
Name TitleRegion1.A6.E63.8: #REF!
Name TitleRegion1.A6.E63.9: #REF!

Sheet Combined
A1: Date | B1: Total Enrollees | C1: Delta Total | D1: Total Group VIII | E1: Delta VIII | F1: Number of States in Group VIII
A2: 43101 | B2: ='January-2018'!B64 -> 77061511 | C2: 0 | D2: ='January-2018'!C64 -> 15805637 | E2: 0 | F2: 35
A3: 43132 | B3: ='February-2018'!B64 -> 76816414 | C3: =(B3-B2)/B2 -> -0.0031805372 | D3: ='February-2018'!C64 -> 15643345 | E3: =(D3-D2)/D2 -> -0.010267982 | F3: 35
A4: 43160 | B4: ='March-2018'!B64 -> 76672124 | C4: =(B4-B3)/B3 -> -0.0018783746 | D4: ='March-2018'!C64 -> 15628063 | E4: =(D4-D3)/D3 -> -0.00097690104 | F4: 35
A5: 43191 | B5: ='April-2018'!B64 -> 76587909 | C5: =(B5-B4)/B4 -> -0.0010983783 | D5: ='April-2018'!C64 -> 15597932 | E5: =(D5-D4)/D4 -> -0.001928006 | F5: 35
A6: 43221 | B6: ='May-2018'!B64 -> 76388516 | C6: =(B6-B5)/B5 -> -0.0026034527 | D6: ='May-2018'!C64 -> 15563132 | E6: =(D6-D5)/D5 -> -0.002231065 | F6: 35
A7: 43252 | B7: ='June-2018'!B64 -> 75959344 | C7: =(B7-B6)/B6 -> -0.0056182791 | D7: ='June-2018'!C64 -> 15438583 | E7: =(D7-D6)/D6 -> -0.0080028236 | F7: 35
A8: 43282 | B8: ='July-2018'!B64 -> 76353875 | C8: =(B8-B7)/B7 -> 0.0051939759 | D8: ='July-2018'!C64 -> 15448246 | E8: =(D8-D7)/D7 -> 0.00062589941 | F8: 35
A9: 43313 | B9: ='August-2018'!B64 -> 76065396 | C9: =(B9-B8)/B8 -> -0.0037781841 | D9: ='August-2018'!C64 -> 15388683 | E9: =(D9-D8)/D8 -> -0.0038556481 | F9: 35
A10: 43344 | B10: ='September-2018'!B64 -> 75485517 | C10: =(B10-B9)/B9 -> -0.0076234271 | D10: ='September-2018'!C64 -> 15269032 | E10: =(D10-D9)/D9 -> -0.0077752593 | F10: 35
A11: 43374 | B11: ='October-2018'!B64 -> 75799027 | C11: =(B11-B10)/B10 -> 0.004153247 | D11: ='October-2018'!C64 -> 15335170 | E11: =(D11-D10)/D10 -> 0.0043315123 | F11: 35
A12: 43405 | B12: ='November-2018'!B64 -> 75525925 | C12: =(B12-B11)/B11 -> -0.003602975 | D12: ='November-2018'!C64 -> 15223609 | E12: =(D12-D11)/D11 -> -0.007274846 | F12: 35
A13: 43435 | B13: ='December-2018'!B64 -> 74770615 | C13: =(B13-B12)/B12 -> -0.010000672 | D13: ='December-2018'!C64 -> 15151153 | E13: =(D13-D12)/D12 -> -0.0047594496 | F13: 34
A14: 43466 | B14: ='January-2019'!B64 -> 75376060 | C14: =(B14-B13)/B13 -> 0.0080973655 | D14: ='January-2019'!C64 -> 15464581 | E14: =(D14-D13)/D13 -> 0.020686742 | F14: 37
A15: 43497 | B15: ='February-2019'!B64 -> 75153292 | C15: =(B15-B14)/B14 -> -0.0029554211 | D15: ='February-2019'!C64 -> 15448306 | E15: =(D15-D14)/D14 -> -0.0010524048 | F15: 37
A16: 43525 | B16: ='March-2019'!B64 -> 74877560 | C16: =(B16-B15)/B15 -> -0.0036689278 | D16: ='March-2019'!C64 -> 15439030 | E16: =(D16-D15)/D15 -> -0.00060045419 | F16: 37
A17: 43556 | B17: ='April-2019'!B64 -> 75071007 | C17: =(B17-B16)/B16 -> 0.002583511 | D17: ='April-2019'!C64 -> 15462070 | E17: =(D17-D16)/D16 -> 0.0014923217 | F17: 37
A18: 43586 | B18: ='May-2019'!B64 -> 74812854 | C18: =(B18-B17)/B17 -> -0.0034387843 | D18: ='May-2019'!C64 -> 15399528 | E18: =(D18-D17)/D17 -> -0.0040448659 | F18: 37
A19: 43617 | B19: ='June-2019'!B64 -> 74215582 | C19: =(B19-B18)/B18 -> -0.0079835479 | D19: ='June-2019'!C64 -> 15269635 | E19: =(D19-D18)/D18 -> -0.0084348689 | F19: 37
A20: 43647 | B20: ='July-2019'!B64 -> 74488451 | C20: =(B20-B19)/B19 -> 0.0036767077 | D20: ='July-2019'!C64 -> 15037252 | E20: =(D20-D19)/D19 -> -0.015218635 | F20: 37
A21: 43678 | B21: ='August-2019'!B64 -> 75037460 | C21: =(B21-B20)/B20 -> 0.0073703909 | D21: ='August-2019'!C64 -> 15518823 | E21: =(D21-D20)/D20 -> 0.0320252 | F21: 37
A22: 43709 | B22: ='September-2019'!B64 -> 75625105 | C22: =(B22-B21)/B21 -> 0.0078313552 | D22: ='September-2019'!C64 -> 15455475 | E22: =(D22-D21)/D21 -> -0.0040820106 | F22: 37
A23: 43739 | B23: ='October-2019'!B64 -> 75011359 | C23: =(B23-B22)/B22 -> -0.0081156383 | D23: ='October-2019'!C64 -> 15506627 | E23: =(D23-D22)/D22 -> 0.0033096362 | F23: 37
A24: 43770 | B24: ='November-2019'!B64 -> 74622336 | C24: =(B24-B23)/B23 -> -0.0051861879 | D24: ='November-2019'!C64 -> 15430736 | E24: =(D24-D23)/D23 -> -0.0048941011 | F24: 37
A25: 43800 | B25: ='December-2019'!B64 -> 74254894 | C25: =(B25-B24)/B24 -> -0.0049240217 | D25: ='December-2019'!C64 -> 15398703 | E25: =(D25-D24)/D24 -> -0.0020759217 | F25: 37
A26: 43831 | B26: ='January-2020'!B64 -> 74732556 | C26: =(B26-B25)/B25 -> 0.0064327343 | D26: ='January-2020'!C64 -> 15622036 | E26: =(D26-D25)/D25 -> 0.014503364 | F26: 39
A27: 43862 | B27: ='February-2020'!B64 -> 74443888 | C27: =(B27-B26)/B26 -> -0.0038626807 | D27: ='February-2020'!C64 -> 15542456 | E27: =(D27-D26)/D26 -> -0.0050940863 | F27: 39
A28: 43891 | B28: ='March-2020'!B64 -> 74275953 | C28: =(B28-B27)/B27 -> -0.0022558601 | D28: ='March-2020'!C64 -> 15545838 | E28: =(D28-D27)/D27 -> 0.00021759753 | F28: 39
A29: 43922 | B29: ='April-2020'!B64 -> 76114580 | C29: =(B29-B28)/B28 -> 0.024754001 | D29: ='April-2020'!C64 -> 16122919 | E29: =(D29-D28)/D28 -> 0.037121254 | F29: 39
A30: 43952 | B30: ='May-2020'!B64 -> 77169947 | C30: =(B30-B29)/B29 -> 0.013865504 | D30: ='May-2020'!C64 -> 16440132 | E30: =(D30-D29)/D29 -> 0.019674663 | F30: 39
A31: 43983 | B31: ='June-2020'!B64 -> 78055480 | C31: =(B31-B30)/B30 -> 0.011475102 | D31: ='June-2020'!C64 -> 16755755 | E31: =(D31-D30)/D30 -> 0.019198325 | F31: 39
A32: 44013 | B32: ='July-2020'!B64 -> 79309251 | C32: =(B32-B31)/B31 -> 0.016062562 | D32: ='July-2020'!C64 -> 17166056 | E32: =(D32-D31)/D31 -> 0.024487169 | F32: 39
A33: 44044 | B33: ='August-2020'!B64 -> 80202982 | C33: =(B33-B32)/B32 -> 0.011268938 | D33: ='August-2020'!C64 -> 17501260 | E33: =(D33-D32)/D32 -> 0.019527141 | F33: 39
A34: 44075 | B34: ='September-2020'!B64 -> 80938780 | C34: =(B34-B33)/B33 -> 0.0091741975 | D34: ='September-2020'!C64 -> 17740750 | E34: =(D34-D33)/D33 -> 0.013684158 | F34: 39
A35: 44105 | B35: ='October-2020'!B64 -> 83848958 | C35: =(B35-B34)/B34 -> 0.035955299 | D35: ='October-2020'!C64 -> 18649336 | E35: =(D35-D34)/D34 -> 0.051214633 | F35: 40
A36: 44136 | B36: ='November-2020'!B64 -> 85021129 | C36: =(B36-B35)/B35 -> 0.013979554 | D36: ='November-2020'!C64 -> 18365572 | E36: =(D36-D35)/D35 -> -0.01521577 | F36: 40
A37: 44166 | B37: ='December-2020'!B64 -> 83327207 | C37: =(B37-B36)/B36 -> -0.019923542 | D37: ='December-2020'!C64 -> 18740932 | E37: =(D37-D36)/D36 -> 0.020438242 | F37: 40
A38: 44197 | B38: ='January-2021'!B64 -> 84904129 | C38: =(B38-B37)/B37 -> 0.018924455 | D38: ='January-2021'!C64 -> 19346158 | E38: =(D38-D37)/D37 -> 0.032294338 | F38: 40
A39: 44228 | B39: ='February-2021'!B64 -> 85397214 | C39: =(B39-B38)/B38 -> 0.0058075503 | D39: ='February-2021'!C64 -> 19570667 | E39: =(D39-D38)/D38 -> 0.011604836 | F39: 40
A40: 44256 | B40: ='March-2021'!B64 -> 85910366 | C40: =(B40-B39)/B39 -> 0.0060090017 | D40: ='March-2021'!C64 -> 19782431 | E40: =(D40-D39)/D39 -> 0.010820479 | F40: 40
...

Sheet January-2018
A1: Total Medicaid Enrollees - VIII Group Break Out Report
A2: January-2018
C3: Updated August 2019
A4: Reported on the CMS-64
A7: State | B7: Total Medicaid Enrollees | C7: Total VIII Group Enrollees | D7: Total VIII Group Newly Eligible Enrollees | E7: Total VIII Group Not Newly Eligible Enrollees
A8: Alabama | B8: 1020587 | C8: N/A | D8: N/A | E8: N/A
A9: Alaska | B9: 196284 | C9: 42966 | D9: 42938 | E9: 28
A10: Amer. Samoa | B10: 27898 | C10: N/A | D10: N/A | E10: N/A
A11: Arizona | B11: 1912427 | C11: 426466 | D11: 111692 | E11: 314774
A12: Arkansas | B12: 920504 | C12: 294581 | D12: 294263 | E12: 318
A13: California | B13: 13175429 | C13: 3847630 | D13: 3847630 | E13: 0
A14: Colorado | B14: 1303683 | C14: 410736 | D14: 408472 | E14: 2264
A15: Connecticut | B15: 920198 | C15: 242204 | D15: 222150 | E15: 20054
A16: Delaware | B16: 211708 | C16: 63045 | D16: 10538 | E16: 52507
A17: Dist. Of Col. | B17: 263558 | C17: 112784 | D17: 71290 | E17: 41494
A18: Florida | B18: 3993964 | C18: N/A | D18: N/A | E18: N/A
A19: Georgia | B19: 1955309 | C19: N/A | D19: N/A | E19: N/A
A20: Guam | B20: 35942 | C20: 3871 | D20: N/A | E20: 3871
A21: Hawaii | B21: 330477 | C21: 120260 | D21: 22747 | E21: 97513
A22: Idaho | B22: 309471 | C22: N/A | D22: N/A | E22: N/A
A23: Illinois | B23: 2943884 | C23: 751967 | D23: 645732 | E23: 106235
A24: Indiana | B24: 1356203 | C24: 446208 | D24: 326576 | E24: 119632
A25: Iowa | B25: 594982 | C25: 157220 | D25: 144106 | E25: 13114
A26: Kansas | B26: 374385 | C26: N/A | D26: N/A | E26: N/A
A27: Kentucky | B27: 1353473 | C27: 492959 | D27: 492959 | E27: 0
A28: Louisiana | B28: 1647299 | C28: 473172 | D28: 473172 | E28: 0
A29: Maine | B29: 256182 | C29: 0 | D29: 0 | E29: 0
A30: Maryland | B30: 1228669 | C30: 311497 | D30: 311497 | E30: 0
A31: Massachusetts | B31: 1809251 | C31: 369509 | D31: 0 | E31: 369509
A32: Michigan | B32: 2445117 | C32: 694972 | D32: 633228 | E32: 61744
A33: Minnesota | B33: 1107477 | C33: 210270 | D33: 209570 | E33: 700
A34: Mississippi | B34: 700020 | C34: N/A | D34: N/A | E34: N/A
A35: Missouri | B35: 968154 | C35: N/A | D35: N/A | E35: N/A
A36: Montana | B36: 256839 | C36: 94916 | D36: 94916 | E36: 0
A37: N. Mariana Islands | B37: 1492 | C37: N/A | D37: N/A | E37: N/A
A38: Nebraska | B38: 245972 | C38: N/A | D38: N/A | E38: N/A
A39: Nevada | B39: 598715 | C39: 215236 | D39: 215236 | E39: 0
A40: New Hampshire | B40: 191335 | C40: 56780 | D40: 56508 | E40: 272
A41: New Jersey | B41: 1699765 | C41: 568364 | D41: 568364 | E41: 0
A42: New Mexico | B42: 863477 | C42: 257654 | D42: 257654 | E42: 0
...

Sheet February-2018
A1: Total Medicaid Enrollees - VIII Group Break Out Report
A2: February-2018
C3: Updated August 2019
A4: Reported on the CMS-64
A7: State | B7: Total Medicaid Enrollees | C7: Total VIII Group Enrollees | D7: Total VIII Group Newly Eligible Enrollees | E7: Total VIII Group Not Newly Eligible Enrollees
A8: Alabama | B8: 1018967 | C8: N/A | D8: N/A | E8: N/A
A9: Alaska | B9: 196618 | C9: 43303 | D9: 43271 | E9: 32
A10: Amer. Samoa | B10: 27898 | C10: N/A | D10: N/A | E10: N/A
A11: Arizona | B11: 1889445 | C11: 420428 | D11: 109296 | E11: 311132
A12: Arkansas | B12: 929130 | C12: 300840 | D12: 300546 | E12: 294
A13: California | B13: 13106525 | C13: 3826607 | D13: 3826607 | E13: 0
A14: Colorado | B14: 1298809 | C14: 410725 | D14: 408481 | E14: 2244
A15: Connecticut | B15: 913961 | C15: 241433 | D15: 221086 | E15: 20347
A16: Delaware | B16: 211567 | C16: 63099 | D16: 10492 | E16: 52607
A17: Dist. Of Col. | B17: 264587 | C17: 113085 | D17: 71873 | E17: 41212
A18: Florida | B18: 3968314 | C18: N/A | D18: N/A | E18: N/A
A19: Georgia | B19: 1960635 | C19: N/A | D19: N/A | E19: N/A
A20: Guam | B20: 35693 | C20: 3892 | D20: N/A | E20: 3892
A21: Hawaii | B21: 331067 | C21: 120890 | D21: 22889 | E21: 98001
A22: Idaho | B22: 307284 | C22: N/A | D22: N/A | E22: N/A
A23: Illinois | B23: 2892062 | C23: 737515 | D23: 631243 | E23: 106272
A24: Indiana | B24: 1346039 | C24: 319894 | D24: 319894 | E24: 0
A25: Iowa | B25: 598557 | C25: 159281 | D25: 146143 | E25: 13138
A26: Kansas | B26: 370313 | C26: N/A | D26: N/A | E26: N/A
A27: Kentucky | B27: 1356170 | C27: 493607 | D27: 493607 | E27: 0
A28: Louisiana | B28: 1647411 | C28: 476258 | D28: 476258 | E28: 0
A29: Maine | B29: 256424 | C29: 0 | D29: 0 | E29: 0
A30: Maryland | B30: 1233989 | C30: 312583 | D30: 312583 | E30: 0
A31: Massachusetts | B31: 1817350 | C31: 376408 | D31: 0 | E31: 376408
A32: Michigan | B32: 2446407 | C32: 696572 | D32: 635680 | E32: 60892
A33: Minnesota | B33: 1095709 | C33: 206685 | D33: 205983 | E33: 702
A34: Mississippi | B34: 696685 | C34: N/A | D34: N/A | E34: N/A
A35: Missouri | B35: 963062 | C35: N/A | D35: N/A | E35: N/A
A36: Montana | B36: 257398 | C36: 95667 | D36: 95667 | E36: 0
A37: N. Mariana Islands | B37: 1196 | C37: N/A | D37: N/A | E37: N/A
A38: Nebraska | B38: 246679 | C38: N/A | D38: N/A | E38: N/A
A39: Nevada | B39: 598712 | C39: 214570 | D39: 214570 | E39: 0
A40: New Hampshire | B40: 190733 | C40: 56186 | D40: 55908 | E40: 278
A41: New Jersey | B41: 1699435 | C41: 568669 | D41: 568669 | E41: 0
A42: New Mexico | B42: 859338 | C42: 257150 | D42: 257150 | E42: 0
...

Sheet March-2018
A1: Total Medicaid Enrollees - VIII Group Break Out Report
A2: March-2018
C3: Updated August 2019
A4: Reported on the CMS-64
A7: State | B7: Total Medicaid Enrollees | C7: Total VIII Group Enrollees | D7: Total VIII Group Newly Eligible Enrollees | E7: Total VIII Group Not Newly Eligible Enrollees
A8: Alabama | B8: 1022959 | C8: N/A | D8: N/A | E8: N/A
A9: Alaska | B9: 197607 | C9: 43817 | D9: 43788 | E9: 29
A10: Amer. Samoa | B10: 27898 | C10: N/A | D10: N/A | E10: N/A
A11: Arizona | B11: 1871923 | C11: 415803 | D11: 107641 | E11: 308162
A12: Arkansas | B12: 922157 | C12: 292573 | D12: 292299 | E12: 274
A13: California | B13: 12966593 | C13: 3787079 | D13: 3787079 | E13: 0
A14: Colorado | B14: 1294260 | C14: 415324 | D14: 413149 | E14: 2175
A15: Connecticut | B15: 927932 | C15: 246769 | D15: 225756 | E15: 21013
A16: Delaware | B16: 210486 | C16: 62756 | D16: 10293 | E16: 52463
A17: Dist. Of Col. | B17: 261661 | C17: 110826 | D17: 70172 | E17: 40654
A18: Florida | B18: 3917285 | C18: N/A | D18: N/A | E18: N/A
A19: Georgia | B19: 1963489 | C19: N/A | D19: N/A | E19: N/A
A20: Guam | B20: 35203 | C20: 3869 | D20: N/A | E20: 3869
A21: Hawaii | B21: 331796 | C21: 121219 | D21: 22886 | E21: 98333
A22: Idaho | B22: 299518 | C22: N/A | D22: N/A | E22: N/A
A23: Illinois | B23: 2867512 | C23: 731008 | D23: 624350 | E23: 106658
A24: Indiana | B24: 1327002 | C24: 310196 | D24: 310196 | E24: 0
A25: Iowa | B25: 600397 | C25: 161393 | D25: 148219 | E25: 13174
A26: Kansas | B26: 370031 | C26: N/A | D26: N/A | E26: N/A
A27: Kentucky | B27: 1357355 | C27: 492751 | D27: 492751 | E27: 0
A28: Louisiana | B28: 1645807 | C28: 478722 | D28: 478722 | E28: 0
A29: Maine | B29: 257452 | C29: 0 | D29: 0 | E29: 0
A30: Maryland | B30: 1237993 | C30: 313593 | D30: 313593 | E30: 0
A31: Massachusetts | B31: 2007685 | C31: 432659 | D31: 0 | E31: 432659
A32: Michigan | B32: 2450490 | C32: 699032 | D32: 638686 | E32: 60346
A33: Minnesota | B33: 1078140 | C33: 202237 | D33: 201547 | E33: 690
A34: Mississippi | B34: 692063 | C34: N/A | D34: N/A | E34: N/A
A35: Missouri | B35: 958954 | C35: N/A | D35: N/A | E35: N/A
A36: Montana | B36: 256778 | C36: 96040 | D36: 96040 | E36: 0
A37: N. Mariana Islands | B37: 1473 | C37: N/A | D37: N/A | E37: N/A
A38: Nebraska | B38: 247459 | C38: N/A | D38: N/A | E38: N/A
A39: Nevada | B39: 598902 | C39: 214266 | D39: 214266 | E39: 0
A40: New Hampshire | B40: 189766 | C40: 55736 | D40: 55450 | E40: 286
A41: New Jersey | B41: 1690042 | C41: 567189 | D41: 567189 | E41: 0
A42: New Mexico | B42: 855320 | C42: 256228 | D42: 256228 | E42: 0
...

Sheet April-2018
A1: Total Medicaid Enrollees - VIII Group Break Out Report
A2: April-2018
C3: Updated August 2019
A4: Reported on the CMS-64
A7: State | B7: Total Medicaid Enrollees | C7: Total VIII Group Enrollees | D7: Total VIII Group Newly Eligible Enrollees | E7: Total VIII Group Not Newly Eligible Enrollees
A8: Alabama | B8: 1024662 | C8: N/A | D8: N/A | E8: N/A
A9: Alaska | B9: 198425 | C9: 44328 | D9: 44304 | E9: 24
A10: Amer. Samoa | B10: 27898 | C10: N/A | D10: N/A | E10: N/A
A11: Arizona | B11: 1870574 | C11: 414373 | D11: 106605 | E11: 307768
A12: Arkansas | B12: 925643 | C12: 292602 | D12: 292349 | E12: 253
A13: California | B13: 13081202 | C13: 3823273 | D13: 3823273 | E13: 0
A14: Colorado | B14: 1282265 | C14: 411009 | D14: 404471 | E14: 6538
A15: Connecticut | B15: 927503 | C15: 246015 | D15: 224785 | E15: 21230
A16: Delaware | B16: 209887 | C16: 62284 | D16: 10034 | E16: 52250
A17: Dist. Of Col. | B17: 260704 | C17: 110199 | D17: 69662 | E17: 40537
A18: Florida | B18: 3931883 | C18: N/A | D18: N/A | E18: N/A
A19: Georgia | B19: 1956021 | C19: N/A | D19: N/A | E19: N/A
A20: Guam | B20: 36260 | C20: 3995 | D20: N/A | E20: 3995
A21: Hawaii | B21: 330439 | C21: 120403 | D21: 22744 | E21: 97659
A22: Idaho | B22: 293894 | C22: N/A | D22: N/A | E22: N/A
A23: Illinois | B23: 2837020 | C23: 720375 | D23: 613844 | E23: 106531
A24: Indiana | B24: 1350223 | C24: 314421 | D24: 314421 | E24: 0
A25: Iowa | B25: 603888 | C25: 163590 | D25: 150142 | E25: 13448
A26: Kansas | B26: 373438 | C26: N/A | D26: N/A | E26: N/A
A27: Kentucky | B27: 1336657 | C27: 473576 | D27: 473576 | E27: 0
A28: Louisiana | B28: 1650457 | C28: 483884 | D28: 483884 | E28: 0
A29: Maine | B29: 256843 | C29: 0 | D29: 0 | E29: 0
A30: Maryland | B30: 1235103 | C30: 312481 | D30: 312481 | E30: 0
A31: Massachusetts | B31: 1834489 | C31: 385266 | D31: 0 | E31: 385266
A32: Michigan | B32: 2444734 | C32: 697940 | D32: 638327 | E32: 59613
A33: Minnesota | B33: 1107289 | C33: 207469 | D33: 206853 | E33: 616
A34: Mississippi | B34: 690180 | C34: N/A | D34: N/A | E34: N/A
A35: Missouri | B35: 961840 | C35: N/A | D35: N/A | E35: N/A
A36: Montana | B36: 260387 | C36: 97926 | D36: 97926 | E36: 0
A37: N. Mariana Islands | B37: 1212 | C37: N/A | D37: N/A | E37: N/A
A38: Nebraska | B38: 247880 | C38: N/A | D38: N/A | E38: N/A
A39: Nevada | B39: 600661 | C39: 214869 | D39: 214869 | E39: 0
A40: New Hampshire | B40: 189480 | C40: 55881 | D40: 55590 | E40: 291
A41: New Jersey | B41: 1693994 | C41: 567110 | D41: 567110 | E41: 0
A42: New Mexico | B42: 856413 | C42: 257678 | D42: 257678 | E42: 0
...

Sheet May-2018
A1: Total Medicaid Enrollees - VIII Group Break Out Report
A2: May-2018
C3: Updated August 2019
A4: Reported on the CMS-64
A7: State | B7: Total Medicaid Enrollees | C7: Total VIII Group Enrollees | D7: Total VIII Group Newly Eligible Enrollees | E7: Total VIII Group Not Newly Eligible Enrollees
A8: Alabama | B8: 1020672 | C8: N/A | D8: N/A | E8: N/A
A9: Alaska | B9: 198535 | C9: 44653 | D9: 44628 | E9: 25
A10: Amer. Samoa | B10: 27898 | C10: N/A | D10: N/A | E10: N/A
A11: Arizona | B11: 1868275 | C11: 413377 | D11: 105782 | E11: 307595
A12: Arkansas | B12: 920752 | C12: 288909 | D12: 288507 | E12: 402
A13: California | B13: 13008201 | C13: 3801552 | D13: 3801552 | E13: 0
A14: Colorado | B14: 1281495 | C14: 411448 | D14: 404895 | E14: 6553
A15: Connecticut | B15: 922726 | C15: 246442 | D15: 225215 | E15: 21227
A16: Delaware | B16: 209914 | C16: 62228 | D16: 9993 | E16: 52235
A17: Dist. Of Col. | B17: 260422 | C17: 109689 | D17: 69206 | E17: 40483
A18: Florida | B18: 3882589 | C18: N/A | D18: N/A | E18: N/A
A19: Georgia | B19: 1956791 | C19: N/A | D19: N/A | E19: N/A
A20: Guam | B20: 36209 | C20: 4038 | D20: N/A | E20: 4038
A21: Hawaii | B21: 327989 | C21: 119145 | D21: 22305 | E21: 96840
A22: Idaho | B22: 295367 | C22: N/A | D22: N/A | E22: N/A
A23: Illinois | B23: 2850842 | C23: 725225 | D23: 618109 | E23: 107116
A24: Indiana | B24: 1333123 | C24: 310612 | D24: 310612 | E24: 0
A25: Iowa | B25: 603493 | C25: 164495 | D25: 150962 | E25: 13533
A26: Kansas | B26: 364986 | C26: N/A | D26: N/A | E26: N/A
A27: Kentucky | B27: 1333466 | C27: 470924 | D27: 470924 | E27: 0
A28: Louisiana | B28: 1647111 | C28: 485112 | D28: 485112 | E28: 0
A29: Maine | B29: 256936 | C29: 0 | D29: 0 | E29: 0
A30: Maryland | B30: 1229917 | C30: 311423 | D30: 311423 | E30: 0
A31: Massachusetts | B31: 1848444 | C31: 391857 | D31: 0 | E31: 391857
A32: Michigan | B32: 2437948 | C32: 693448 | D32: 635722 | E32: 57726
A33: Minnesota | B33: 1098818 | C33: 204765 | D33: 204047 | E33: 718
A34: Mississippi | B34: 687906 | C34: N/A | D34: N/A | E34: N/A
A35: Missouri | B35: 964163 | C35: N/A | D35: N/A | E35: N/A
A36: Montana | B36: 260270 | C36: 98314 | D36: 98314 | E36: 0
A37: N. Mariana Islands | B37: 1400 | C37: N/A | D37: N/A | E37: N/A
A38: Nebraska | B38: 247273 | C38: N/A | D38: N/A | E38: N/A
A39: Nevada | B39: 601011 | C39: 215101 | D39: 215101 | E39: 0
A40: New Hampshire | B40: 188917 | C40: 55651 | D40: 55368 | E40: 283
A41: New Jersey | B41: 1692408 | C41: 566732 | D41: 566732 | E41: 0
A42: New Mexico | B42: 849268 | C42: 255142 | D42: 255142 | E42: 0
...

Sheet June-2018
A1: Total Medicaid Enrollees - VIII Group Break Out Report
A2: June-2018
C3: Updated August 2019
A4: Reported on the CMS-64
A7: State | B7: Total Medicaid Enrollees | C7: Total VIII Group Enrollees | D7: Total VIII Group Newly Eligible Enrollees | E7: Total VIII Group Not Newly Eligible Enrollees
A8: Alabama | B8: 1021657 | C8: N/A | D8: N/A | E8: N/A
A9: Alaska | B9: 198729 | C9: 44930 | D9: 44905 | E9: 25
A10: Amer. Samoa | B10: 27898 | C10: N/A | D10: N/A | E10: N/A
A11: Arizona | B11: 1864623 | C11: 412927 | D11: 105049 | E11: 307878
A12: Arkansas | B12: 917921 | C12: 284342 | D12: 283961 | E12: 381
A13: California | B13: 12874106 | C13: 3763860 | D13: 3763860 | E13: 0
A14: Colorado | B14: 1296301 | C14: 409143 | D14: 402412 | E14: 6731
A15: Connecticut | B15: 927265 | C15: 248443 | D15: 226951 | E15: 21492
A16: Delaware | B16: 209755 | C16: 62188 | D16: 9926 | E16: 52262
A17: Dist. Of Col. | B17: 259746 | C17: 108718 | D17: 68205 | E17: 40513
A18: Florida | B18: 3852558 | C18: N/A | D18: N/A | E18: N/A
A19: Georgia | B19: 1957737 | C19: N/A | D19: N/A | E19: N/A
A20: Guam | B20: 35905 | C20: 4032 | D20: N/A | E20: 4032
A21: Hawaii | B21: 324002 | C21: 117546 | D21: 21859 | E21: 95687
A22: Idaho | B22: 296090 | C22: N/A | D22: N/A | E22: N/A
A23: Illinois | B23: 2827783 | C23: 717537 | D23: 610604 | E23: 106933
A24: Indiana | B24: 1310854 | C24: 305782 | D24: 305782 | E24: 0
A25: Iowa | B25: 602532 | C25: 165509 | D25: 151969 | E25: 13540
A26: Kansas | B26: 363414 | C26: N/A | D26: N/A | E26: N/A
A27: Kentucky | B27: 1328039 | C27: 467275 | D27: 467275 | E27: 0
A28: Louisiana | B28: 1638252 | C28: 482248 | D28: 482248 | E28: 0
A29: Maine | B29: 255517 | C29: 0 | D29: 0 | E29: 0
A30: Maryland | B30: 1218122 | C30: 307690 | D30: 307690 | E30: 0
A31: Massachusetts | B31: 1807979 | C31: 373499 | D31: 0 | E31: 373499
A32: Michigan | B32: 2437622 | C32: 688853 | D32: 634323 | E32: 54530
A33: Minnesota | B33: 1084832 | C33: 201427 | D33: 200712 | E33: 715
A34: Mississippi | B34: 683577 | C34: N/A | D34: N/A | E34: N/A
A35: Missouri | B35: 961679 | C35: N/A | D35: N/A | E35: N/A
A36: Montana | B36: 258600 | C36: 97834 | D36: 97834 | E36: 0
A37: N. Mariana Islands | B37: 1416 | C37: N/A | D37: N/A | E37: N/A
A38: Nebraska | B38: 245882 | C38: N/A | D38: N/A | E38: N/A
A39: Nevada | B39: 600837 | C39: 214489 | D39: 214489 | E39: 0
A40: New Hampshire | B40: 187628 | C40: 55188 | D40: 54907 | E40: 281
A41: New Jersey | B41: 1687716 | C41: 566209 | D41: 566209 | E41: 0
A42: New Mexico | B42: 838445 | C42: 251909 | D42: 251909 | E42: 0
...

Sheet July-2018
A1: Total Medicaid Enrollees - VIII Group Break Out Report
A2: July-2018
A3: Updated February 2020
A4: Reported on the CMS-64
A7: State | B7: Total Medicaid Enrollees | C7: Total VIII Group Enrollees | D7: Total VIII Group Newly Eligible Enrollees | E7: Total VIII Group Not Newly Eligible Enrollees
A8: Alabama | B8: 1019417 | C8: N/A | D8: N/A | E8: N/A
A9: Alaska | B9: 205437 | C9: 47522 | D9: 47520 | E9: 2
A10: Amer. Samoa * | B10: 27898 | C10: N/A | D10: N/A | E10: N/A
A11: Arizona | B11: 1870925 | C11: 413637 | D11: 105382 | E11: 308255
A12: Arkansas | B12: 915127 | C12: 280923 | D12: 280441 | E12: 482
A13: California | B13: 12953106 | C13: 3787702 | D13: 3787702 | E13: 0
A14: Colorado | B14: 1295757 | C14: 405756 | D14: 398806 | E14: 6950
A15: Connecticut | B15: 928800 | C15: 250696 | D15: 229072 | E15: 21624
A16: Delaware | B16: 210857 | C16: 62684 | D16: 10040 | E16: 52644
A17: Dist. Of Col. | B17: 261071 | C17: 110308 | D17: 68937 | E17: 41371
A18: Florida | B18: 3886256 | C18: N/A | D18: N/A | E18: N/A
A19: Georgia | B19: 1984150 | C19: N/A | D19: N/A | E19: N/A
A20: Guam | B20: 36382 | C20: 4041 | D20: N/A | E20: 4041
A21: Hawaii | B21: 322003 | C21: 116486 | D21: 21627 | E21: 94859
A22: Idaho | B22: 299571 | C22: N/A | D22: N/A | E22: N/A
A23: Illinois | B23: 2835995 | C23: 724881 | D23: 617626 | E23: 107255
A24: Indiana | B24: 1332154 | C24: 304739 | D24: 304739 | E24: 0
A25: Iowa | B25: 603783 | C25: 166288 | D25: 152389 | E25: 13899
A26: Kansas | B26: 375489 | C26: N/A | D26: N/A | E26: N/A
A27: Kentucky | B27: 1324040 | C27: 464074 | D27: 464074 | E27: 0
A28: Louisiana | B28: 1644548 | C28: 484602 | D28: 484602 | E28: 0
A29: Maine | B29: 253059 | C29: 0 | D29: 0 | E29: 0
A30: Maryland | B30: 1213505 | C30: 306497 | D30: 306497 | E30: 0
A31: Massachusetts | B31: 1798421 | C31: 354871 | D31: 0 | E31: 354871
A32: Michigan | B32: 2434780 | C32: 686125 | D32: 626607 | E32: 59518
A33: Minnesota | B33: 1107314 | C33: 205850 | D33: 205091 | E33: 759
A34: Mississippi | B34: 678980 | C34: N/A | D34: N/A | E34: N/A
A35: Missouri | B35: 941393 | C35: N/A | D35: N/A | E35: N/A
A36: Montana | B36: 260463 | C36: 98630 | D36: 98630 | E36: 0
A37: N. Mariana Islands | B37: 17402 | C37: N/A | D37: N/A | E37: N/A
A38: Nebraska | B38: 245360 | C38: N/A | D38: N/A | E38: N/A
A39: Nevada | B39: 601200 | C39: 214714 | D39: 214714 | E39: 0
A40: New Hampshire | B40: 187403 | C40: 55149 | D40: 54872 | E40: 277
A41: New Jersey | B41: 1690311 | C41: 564120 | D41: 564120 | E41: 0
A42: New Mexico | B42: 838548 | C42: 251347 | D42: 251347 | E42: 0
...

Sheet August-2018
A1: Total Medicaid Enrollees - VIII Group Break Out Report
A2: August-2018
A3: Updated February 2020
A4: Reported on the CMS-64
A7: State | B7: Total Medicaid Enrollees | C7: Total VIII Group Enrollees | D7: Total VIII Group Newly Eligible Enrollees | E7: Total VIII Group Not Newly Eligible Enrollees
A8: Alabama | B8: 1021951 | C8: N/A | D8: N/A | E8: N/A
A9: Alaska | B9: 206259 | C9: 47883 | D9: 47882 | E9: 1
A10: Amer. Samoa * | B10: 27898 | C10: N/A | D10: N/A | E10: N/A
A11: Arizona | B11: 1873080 | C11: 414203 | D11: 106007 | E11: 308196
A12: Arkansas | B12: 914767 | C12: 275602 | D12: 274810 | E12: 792
A13: California | B13: 12895963 | C13: 3773620 | D13: 3773620 | E13: 0
A14: Colorado | B14: 1298991 | C14: 410093 | D14: 403062 | E14: 7031
A15: Connecticut | B15: 941173 | C15: 254526 | D15: 232838 | E15: 21688
A16: Delaware | B16: 211280 | C16: 62798 | D16: 10046 | E16: 52752
A17: Dist. Of Col. | B17: 260790 | C17: 109859 | D17: 68512 | E17: 41347
A18: Florida | B18: 3850158 | C18: N/A | D18: N/A | E18: N/A
A19: Georgia | B19: 1941288 | C19: N/A | D19: N/A | E19: N/A
A20: Guam | B20: 36322 | C20: 4039 | D20: N/A | E20: 4039
A21: Hawaii | B21: 320843 | C21: 115454 | D21: 21523 | E21: 93931
A22: Idaho | B22: 301537 | C22: N/A | D22: N/A | E22: N/A
A23: Illinois | B23: 2819278 | C23: 718945 | D23: 611650 | E23: 107295
A24: Indiana | B24: 1320972 | C24: 302840 | D24: 302840 | E24: 0
A25: Iowa | B25: 603495 | C25: 167205 | D25: 153121 | E25: 14084
A26: Kansas | B26: 375289 | C26: N/A | D26: N/A | E26: N/A
A27: Kentucky | B27: 1320886 | C27: 460997 | D27: 460997 | E27: 0
A28: Louisiana | B28: 1646050 | C28: 486291 | D28: 486291 | E28: 0
A29: Maine | B29: 253084 | C29: 0 | D29: 0 | E29: 0
A30: Maryland | B30: 1218003 | C30: 308613 | D30: 308613 | E30: 0
A31: Massachusetts | B31: 1758706 | C31: 348278 | D31: 0 | E31: 348278
A32: Michigan | B32: 2435746 | C32: 684662 | D32: 625175 | E32: 59487
A33: Minnesota | B33: 1096403 | C33: 202648 | D33: 201759 | E33: 889
A34: Mississippi | B34: 678243 | C34: N/A | D34: N/A | E34: N/A
A35: Missouri | B35: 943536 | C35: N/A | D35: N/A | E35: N/A
A36: Montana | B36: 258642 | C36: 98389 | D36: 98389 | E36: 0
A37: N. Mariana Islands | B37: 17244 | C37: N/A | D37: N/A | E37: N/A
A38: Nebraska | B38: 246589 | C38: N/A | D38: N/A | E38: N/A
A39: Nevada | B39: 602322 | C39: 214260 | D39: 214260 | E39: 0
A40: New Hampshire | B40: 187247 | C40: 55119 | D40: 54831 | E40: 288
A41: New Jersey | B41: 1685266 | C41: 561470 | D41: 561470 | E41: 0
A42: New Mexico | B42: 835672 | C42: 250673 | D42: 250673 | E42: 0
...

Sheet September-2018
A1: Total Medicaid Enrollees - VIII Group Break Out Report
A2: September-2018
A3: Updated February 2020
A4: Reported on the CMS-64
A7: State | B7: Total Medicaid Enrollees | C7: Total VIII Group Enrollees | D7: Total VIII Group Newly Eligible Enrollees | E7: Total VIII Group Not Newly Eligible Enrollees
A8: Alabama | B8: 1025250 | C8: N/A | D8: N/A | E8: N/A
A9: Alaska | B9: 206277 | C9: 48272 | D9: 48270 | E9: 2
A10: Amer. Samoa * | B10: 27898 | C10: N/A | D10: N/A | E10: N/A
A11: Arizona | B11: 1880703 | C11: 417074 | D11: 106282 | E11: 310792
A12: Arkansas | B12: 904820 | C12: 266173 | D12: 265322 | E12: 851
A13: California | B13: 12725382 | C13: 3733737 | D13: 3733737 | E13: 0
A14: Colorado | B14: 1300426 | C14: 411490 | D14: 404538 | E14: 6952
A15: Connecticut | B15: 936487 | C15: 256183 | D15: 233395 | E15: 22788
A16: Delaware | B16: 211235 | C16: 62735 | D16: 9984 | E16: 52751
A17: Dist. Of Col. | B17: 260240 | C17: 109131 | D17: 67651 | E17: 41480
A18: Florida | B18: 3723585 | C18: N/A | D18: N/A | E18: N/A
A19: Georgia | B19: 1932732 | C19: N/A | D19: N/A | E19: N/A
A20: Guam | B20: 36128 | C20: 4034 | D20: N/A | E20: 4034
A21: Hawaii | B21: 318337 | C21: 114226 | D21: 21206 | E21: 93020
A22: Idaho | B22: 301897 | C22: N/A | D22: N/A | E22: N/A
A23: Illinois | B23: 2784328 | C23: 710385 | D23: 603602 | E23: 106783
A24: Indiana | B24: 1298758 | C24: 296719 | D24: 296719 | E24: 0
A25: Iowa | B25: 604187 | C25: 167984 | D25: 153533 | E25: 14451
A26: Kansas | B26: 374444 | C26: N/A | D26: N/A | E26: N/A
A27: Kentucky | B27: 1308238 | C27: 454781 | D27: 454781 | E27: 0
A28: Louisiana | B28: 1641821 | C28: 487635 | D28: 487635 | E28: 0
A29: Maine | B29: 251934 | C29: 0 | D29: 0 | E29: 0
A30: Maryland | B30: 1214405 | C30: 307932 | D30: 307932 | E30: 0
A31: Massachusetts | B31: 1742631 | C31: 346875 | D31: 0 | E31: 346875
A32: Michigan | B32: 2432660 | C32: 684366 | D32: 625401 | E32: 58965
A33: Minnesota | B33: 1077132 | C33: 197968 | D33: 196976 | E33: 992
A34: Mississippi | B34: 675028 | C34: N/A | D34: N/A | E34: N/A
A35: Missouri | B35: 929322 | C35: N/A | D35: N/A | E35: N/A
A36: Montana | B36: 252126 | C36: 96177 | D36: 96177 | E36: 0
A37: N. Mariana Islands | B37: 16417 | C37: N/A | D37: N/A | E37: N/A
A38: Nebraska | B38: 245070 | C38: N/A | D38: N/A | E38: N/A
A39: Nevada | B39: 600762 | C39: 213869 | D39: 213869 | E39: 0
A40: New Hampshire | B40: 186728 | C40: 55024 | D40: 54727 | E40: 297
A41: New Jersey | B41: 1674135 | C41: 555514 | D41: 555514 | E41: 0
A42: New Mexico | B42: 826594 | C42: 248307 | D42: 248307 | E42: 0
...

Sheet October-2018
A1: Total Medicaid Enrollees - VIII Group Break Out Report
A2: October-2018
A3: Updated February 2020
A4: Reported on the CMS-64
A7: State | B7: Total Medicaid Enrollees | C7: Total VIII Group Enrollees | D7: Total VIII Group Newly Eligible Enrollees | E7: Total VIII Group Not Newly Eligible Enrollees
A8: Alabama | B8: 1030845 | C8: N/A | D8: N/A | E8: N/A
A9: Alaska | B9: 206088 | C9: 48735 | D9: 48732 | E9: 3
A10: Amer. Samoa * | B10: 28183 | C10: N/A | D10: N/A | E10: N/A
A11: Arizona | B11: 1872908 | C11: 416061 | D11: 106046 | E11: 310015
A12: Arkansas | B12: 872212 | C12: 269136 | D12: 268280 | E12: 856
A13: California | B13: 12875160 | C13: 3790254 | D13: 3790254 | E13: 0
A14: Colorado | B14: 1288644 | C14: 409565 | D14: 402363 | E14: 7202
A15: Connecticut | B15: 935416 | C15: 256847 | D15: 233875 | E15: 22972
A16: Delaware | B16: 219077 | C16: 62623 | D16: 9772 | E16: 52851
A17: Dist. Of Col. | B17: 260411 | C17: 108584 | D17: 67018 | E17: 41566
A18: Florida | B18: 3878529 | C18: N/A | D18: N/A | E18: N/A
A19: Georgia | B19: 1942580 | C19: N/A | D19: N/A | E19: N/A
A20: Guam | B20: 36512 | C20: 4127 | D20: N/A | E20: 4127
A21: Hawaii | B21: 317217 | C21: 113491 | D21: 20999 | E21: 92492
A22: Idaho | B22: 303522 | C22: N/A | D22: N/A | E22: N/A
A23: Illinois | B23: 2749591 | C23: 702914 | D23: 596398 | E23: 106516
A24: Indiana | B24: 1328932 | C24: 303464 | D24: 303464 | E24: 0
A25: Iowa | B25: 606771 | C25: 169110 | D25: 154410 | E25: 14700
A26: Kansas | B26: 374483 | C26: N/A | D26: N/A | E26: N/A
A27: Kentucky | B27: 1299471 | C27: 451805 | D27: 451805 | E27: 0
A28: Louisiana | B28: 1654528 | C28: 494332 | D28: 494332 | E28: 0
A29: Maine | B29: 251140 | C29: 0 | D29: 0 | E29: 0
A30: Maryland | B30: 1214367 | C30: 308841 | D30: 308841 | E30: 0
A31: Massachusetts | B31: 1753049 | C31: 346163 | D31: 0 | E31: 346163
A32: Michigan | B32: 2428592 | C32: 684432 | D32: 626588 | E32: 57844
A33: Minnesota | B33: 1097796 | C33: 202437 | D33: 201489 | E33: 948
A34: Mississippi | B34: 674804 | C34: N/A | D34: N/A | E34: N/A
A35: Missouri | B35: 916574 | C35: N/A | D35: N/A | E35: N/A
A36: Montana | B36: 259669 | C36: 99148 | D36: 99148 | E36: 0
A37: N. Mariana Islands | B37: 16334 | C37: N/A | D37: N/A | E37: N/A
A38: Nebraska | B38: 245662 | C38: N/A | D38: N/A | E38: N/A
A39: Nevada | B39: 599811 | C39: 214196 | D39: 214196 | E39: 0
A40: New Hampshire | B40: 186104 | C40: 54851 | D40: 54553 | E40: 298
A41: New Jersey | B41: 1667572 | C41: 552008 | D41: 552008 | E41: 0
A42: New Mexico | B42: 834585 | C42: 251482 | D42: 251482 | E42: 0
...

Sheet November-2018
A1: Total Medicaid Enrollees - VIII Group Break Out Report
A2: November-2018
A3: Updated February 2020
A4: Reported on the CMS-64
A7: State | B7: Total Medicaid Enrollees | C7: Total VIII Group Enrollees | D7: Total VIII Group Newly Eligible Enrollees | E7: Total VIII Group Not Newly Eligible Enrollees
A8: Alabama | B8: 1029480 | C8: N/A | D8: N/A | E8: N/A
A9: Alaska | B9: 206553 | C9: 49465 | D9: 49460 | E9: 5
A10: Amer. Samoa * | B10: 28183 | C10: N/A | D10: N/A | E10: N/A
A11: Arizona | B11: 1875585 | C11: 417955 | D11: 106001 | E11: 311954
A12: Arkansas | B12: 862562 | C12: 264626 | D12: 263881 | E12: 745
A13: California | B13: 12806573 | C13: 3778550 | D13: 3778548 | E13: 2
A14: Colorado | B14: 1274037 | C14: 400640 | D14: 393453 | E14: 7187
A15: Connecticut | B15: 941142 | C15: 259611 | D15: 236522 | E15: 23089
A16: Delaware | B16: 218580 | C16: 62573 | D16: 9702 | E16: 52871
A17: Dist. Of Col. | B17: 261004 | C17: 108667 | D17: 67073 | E17: 41594
A18: Florida | B18: 3831170 | C18: N/A | D18: N/A | E18: N/A
A19: Georgia | B19: 1942727 | C19: N/A | D19: N/A | E19: N/A
A20: Guam | B20: 36437 | C20: 4151 | D20: N/A | E20: 4151
A21: Hawaii | B21: 315744 | C21: 113064 | D21: 21058 | E21: 92006
A22: Idaho | B22: 303763 | C22: N/A | D22: N/A | E22: N/A
A23: Illinois | B23: 2716062 | C23: 695325 | D23: 588527 | E23: 106798
A24: Indiana | B24: 1314309 | C24: 304042 | D24: 304042 | E24: 0
A25: Iowa | B25: 602886 | C25: 168966 | D25: 154137 | E25: 14829
A26: Kansas | B26: 372581 | C26: N/A | D26: N/A | E26: N/A
A27: Kentucky | B27: 1298359 | C27: 451771 | D27: 451771 | E27: 0
A28: Louisiana | B28: 1649027 | C28: 493404 | D28: 493404 | E28: 0
A29: Maine | B29: 250778 | C29: 0 | D29: 0 | E29: 0
A30: Maryland | B30: 1214140 | C30: 309524 | D30: 309524 | E30: 0
A31: Massachusetts | B31: 1764713 | C31: 271885 | D31: 0 | E31: 271885
A32: Michigan | B32: 2422058 | C32: 683634 | D32: 628160 | E32: 55474
A33: Minnesota | B33: 1084321 | C33: 199057 | D33: 198138 | E33: 919
A34: Mississippi | B34: 672864 | C34: N/A | D34: N/A | E34: N/A
A35: Missouri | B35: 903552 | C35: N/A | D35: N/A | E35: N/A
A36: Montana | B36: 257807 | C36: 98633 | D36: 98633 | E36: 0
A37: N. Mariana Islands | B37: 15871 | C37: N/A | D37: N/A | E37: N/A
A38: Nebraska | B38: 244729 | C38: N/A | D38: N/A | E38: N/A
A39: Nevada | B39: 594711 | C39: 212434 | D39: 212434 | E39: 0
A40: New Hampshire | B40: 185826 | C40: 54920 | D40: 54637 | E40: 283
A41: New Jersey | B41: 1661294 | C41: 551660 | D41: 551660 | E41: 0
A42: New Mexico | B42: 835397 | C42: 252671 | D42: 252671 | E42: 0
...

Sheet December-2018
A1: Total Medicaid Enrollees - VIII Group Break Out Report
A2: December-2018
A3: Updated February 2020
A4: Reported on the CMS-64
A7: State | B7: Total Medicaid Enrollees | C7: Total VIII Group Enrollees | D7: Total VIII Group Newly Eligible Enrollees | E7: Total VIII Group Not Newly Eligible Enrollees
A8: Alabama | B8: 1026849 | C8: N/A | D8: N/A | E8: N/A
A9: Alaska | B9: 206870 | C9: 50050 | D9: 50046 | E9: 4
A10: Amer. Samoa * | B10: 28183 | C10: N/A | D10: N/A | E10: N/A
A11: Arizona | B11: 1875915 | C11: 420159 | D11: 106170 | E11: 313989
A12: Arkansas | B12: 845850 | C12: 256595 | D12: 255852 | E12: 743
A13: California | B13: 12674291 | C13: 3745157 | D13: 3745154 | E13: 3
A14: Colorado | B14: 1267068 | C14: 398485 | D14: 391400 | E14: 7085
A15: Connecticut | B15: 951730 | C15: 264330 | D15: 240657 | E15: 23673
A16: Delaware | B16: 0 | C16: 0 | D16: 0 | E16: 0
A17: Dist. Of Col. | B17: 261096 | C17: 108901 | D17: 67213 | E17: 41688
A18: Florida | B18: 3717196 | C18: N/A | D18: N/A | E18: N/A
A19: Georgia | B19: 1945609 | C19: N/A | D19: N/A | E19: N/A
A20: Guam | B20: 36285 | C20: 4165 | D20: N/A | E20: 4165
A21: Hawaii | B21: 314082 | C21: 112703 | D21: 20972 | E21: 91731
A22: Idaho | B22: 304138 | C22: N/A | D22: N/A | E22: N/A
A23: Illinois | B23: 2681580 | C23: 688386 | D23: 581454 | E23: 106932
A24: Indiana | B24: 1293678 | C24: 301500 | D24: 301500 | E24: 0
A25: Iowa | B25: 604261 | C25: 169743 | D25: 154768 | E25: 14975
A26: Kansas | B26: 372118 | C26: N/A | D26: N/A | E26: N/A
A27: Kentucky | B27: 1292585 | C27: 449995 | D27: 449995 | E27: 0
A28: Louisiana | B28: 1652110 | C28: 495453 | D28: 495453 | E28: 0
A29: Maine | B29: 248113 | C29: 0 | D29: 0 | E29: 0
A30: Maryland | B30: 1211894 | C30: 309758 | D30: 309758 | E30: 0
A31: Massachusetts | B31: 1701088 | C31: 334737 | D31: 0 | E31: 334737
A32: Michigan | B32: 2420714 | C32: 687460 | D32: 633017 | E32: 54443
A33: Minnesota | B33: 1057341 | C33: 192820 | D33: 192256 | E33: 564
A34: Mississippi | B34: 670959 | C34: N/A | D34: N/A | E34: N/A
A35: Missouri | B35: 897164 | C35: N/A | D35: N/A | E35: N/A
A36: Montana | B36: 254940 | C36: 97832 | D36: 97832 | E36: 0
A37: N. Mariana Islands | B37: 15779 | C37: N/A | D37: N/A | E37: N/A
A38: Nebraska | B38: 243681 | C38: N/A | D38: N/A | E38: N/A
A39: Nevada | B39: 591035 | C39: 211278 | D39: 211278 | E39: 0
A40: New Hampshire | B40: 185705 | C40: 55448 | D40: 55172 | E40: 276
A41: New Jersey | B41: 1656601 | C41: 552053 | D41: 552053 | E41: 0
A42: New Mexico | B42: 832586 | C42: 252949 | D42: 252949 | E42: 0
...

Sheet January-2019
A1: Total Medicaid Enrollees - VIII Group Break Out Report
A2: January-2019
A3: Updated February 2020
A4: Reported on the CMS-64
A7: State | B7: Total Medicaid Enrollees | C7: Total VIII Group Enrollees | D7: Total VIII Group Newly Eligible Enrollees | E7: Total VIII Group Not Newly Eligible Enrollees
A8: Alabama | B8: 1030869 | C8: N/A | D8: N/A | E8: N/A
A9: Alaska | B9: 207330 | C9: 50515 | D9: 50512 | E9: 3
A10: Amer. Samoa * | B10: 28183 | C10: N/A | D10: N/A | E10: N/A
A11: Arizona | B11: 1874674 | C11: 421967 | D11: 106458 | E11: 315509
A12: Arkansas | B12: 841490 | C12: 254640 | D12: 253702 | E12: 938
A13: California | B13: 12793749 | C13: 3787369 | D13: 3787362 | E13: 7
A14: Colorado | B14: 1258689 | C14: 389813 | D14: 382675 | E14: 7138
A15: Connecticut | B15: 947355 | C15: 263967 | D15: 240397 | E15: 23570
A16: Delaware | B16: 219338 | C16: 62893 | D16: 9842 | E16: 53051
A17: Dist. Of Col. | B17: 260388 | C17: 108097 | D17: 66620 | E17: 41477
A18: Florida | B18: 3834674 | C18: N/A | D18: N/A | E18: N/A
A19: Georgia | B19: 1961608 | C19: N/A | D19: N/A | E19: N/A
A20: Guam | B20: 36415 | C20: 4196 | D20: N/A | E20: 4196
A21: Hawaii | B21: 313334 | C21: 112080 | D21: 20671 | E21: 91409
A22: Idaho | B22: 293665 | C22: N/A | D22: N/A | E22: N/A
A23: Illinois | B23: 2668561 | C23: 683826 | D23: 576312 | E23: 107514
A24: Indiana | B24: 1320211 | C24: 305297 | D24: 305297 | E24: 0
A25: Iowa | B25: 601388 | C25: 169454 | D25: 153747 | E25: 15707
A26: Kansas | B26: 369499 | C26: N/A | D26: N/A | E26: N/A
A27: Kentucky | B27: 1294292 | C27: 450634 | D27: 450634 | E27: 0
A28: Louisiana | B28: 1679275 | C28: 508604 | D28: 508604 | E28: 0
A29: Maine | B29: 250952 | C29: 2922 | D29: 2922 | E29: 0
A30: Maryland | B30: 1211974 | C30: 309643 | D30: 309643 | E30: 0
A31: Massachusetts | B31: 1481856 | C31: 337206 | D31: 0 | E31: 337206
A32: Michigan | B32: 2421046 | C32: 689970 | D32: 636973 | E32: 52997
A33: Minnesota | B33: 1084410 | C33: 197789 | D33: 197019 | E33: 770
A34: Mississippi | B34: 675003 | C34: N/A | D34: N/A | E34: N/A
A35: Missouri | B35: 895137 | C35: N/A | D35: N/A | E35: N/A
A36: Montana | B36: 259773 | C36: 99861 | D36: 99861 | E36: 0
A37: N. Mariana Islands | B37: 16305 | C37: N/A | D37: N/A | E37: N/A
A38: Nebraska | B38: 244419 | C38: N/A | D38: N/A | E38: N/A
A39: Nevada | B39: 589856 | C39: 211069 | D39: 211069 | E39: 0
A40: New Hampshire | B40: 185469 | C40: 55063 | D40: 54786 | E40: 277
A41: New Jersey | B41: 1651766 | C41: 551242 | D41: 551242 | E41: 0
A42: New Mexico | B42: 837778 | C42: 255147 | D42: 255147 | E42: 0
...

Sheet February-2019
A1: Total Medicaid Enrollees - VIII Group Break Out Report
A2: February-2019
A3: Updated February 2020
A4: Reported on the CMS-64
A7: State | B7: Total Medicaid Enrollees | C7: Total VIII Group Enrollees | D7: Total VIII Group Newly Eligible Enrollees | E7: Total VIII Group Not Newly Eligible Enrollees
A8: Alabama | B8: 1033902 | C8: N/A | D8: N/A | E8: N/A
A9: Alaska | B9: 207050 | C9: 50745 | D9: 50742 | E9: 3
A10: Amer. Samoa * | B10: 28183 | C10: N/A | D10: N/A | E10: N/A
A11: Arizona | B11: 1880317 | C11: 426279 | D11: 107451 | E11: 318828
A12: Arkansas | B12: 832662 | C12: 251077 | D12: 250141 | E12: 936
A13: California | B13: 12724664 | C13: 3768331 | D13: 3767510 | E13: 821
A14: Colorado | B14: 1255515 | C14: 389270 | D14: 382110 | E14: 7160
A15: Connecticut | B15: 953795 | C15: 266839 | D15: 242907 | E15: 23932
A16: Delaware | B16: 219432 | C16: 62843 | D16: 9784 | E16: 53059
A17: Dist. Of Col. | B17: 260789 | C17: 108049 | D17: 66542 | E17: 41507
A18: Florida | B18: 3790751 | C18: N/A | D18: N/A | E18: N/A
A19: Georgia | B19: 1957553 | C19: N/A | D19: N/A | E19: N/A
A20: Guam | B20: 36253 | C20: 4207 | D20: N/A | E20: 4207
A21: Hawaii | B21: 311088 | C21: 110824 | D21: 20336 | E21: 90488
A22: Idaho | B22: 294793 | C22: N/A | D22: N/A | E22: N/A
A23: Illinois | B23: 2638758 | C23: 672921 | D23: 565283 | E23: 107638
A24: Indiana | B24: 1320319 | C24: 309792 | D24: 309792 | E24: 0
A25: Iowa | B25: 604647 | C25: 171352 | D25: 155930 | E25: 15422
A26: Kansas | B26: 364113 | C26: N/A | D26: N/A | E26: N/A
A27: Kentucky | B27: 1290860 | C27: 450566 | D27: 450566 | E27: 0
A28: Louisiana | B28: 1675222 | C28: 507789 | D28: 507789 | E28: 0
A29: Maine | B29: 257551 | C29: 8562 | D29: 8562 | E29: 0
A30: Maryland | B30: 1215940 | C30: 310237 | D30: 310237 | E30: 0
A31: Massachusetts | B31: 1418667 | C31: 320525 | D31: 0 | E31: 320525
A32: Michigan | B32: 2443016 | C32: 697752 | D32: 645158 | E32: 52594
A33: Minnesota | B33: 1067388 | C33: 193550 | D33: 192684 | E33: 866
A34: Mississippi | B34: 674568 | C34: N/A | D34: N/A | E34: N/A
A35: Missouri | B35: 890169 | C35: N/A | D35: N/A | E35: N/A
A36: Montana | B36: 258991 | C36: 99706 | D36: 99706 | E36: 0
A37: N. Mariana Islands | B37: 15963 | C37: N/A | D37: N/A | E37: N/A
A38: Nebraska | B38: 245052 | C38: N/A | D38: N/A | E38: N/A
A39: Nevada | B39: 587891 | C39: 210227 | D39: 210227 | E39: 0
A40: New Hampshire | B40: 185135 | C40: 54590 | D40: 54307 | E40: 283
A41: New Jersey | B41: 1639444 | C41: 545379 | D41: 545379 | E41: 0
A42: New Mexico | B42: 836101 | C42: 255681 | D42: 255681 | E42: 0
...

Sheet March-2019
A1: Total Medicaid Enrollees - VIII Group Break Out Report
A2: March-2019
A3: Updated February 2020
A4: Reported on the CMS-64
A7: State | B7: Total Medicaid Enrollees | C7: Total VIII Group Enrollees | D7: Total VIII Group Newly Eligible Enrollees | E7: Total VIII Group Not Newly Eligible Enrollees
A8: Alabama | B8: 1033512 | C8: N/A | D8: N/A | E8: N/A
A9: Alaska | B9: 206812 | C9: 50871 | D9: 50867 | E9: 4
A10: Amer. Samoa * | B10: 28183 | C10: N/A | D10: N/A | E10: N/A
A11: Arizona | B11: 1876939 | C11: 426199 | D11: 107490 | E11: 318709
A12: Arkansas | B12: 825029 | C12: 247947 | D12: 246996 | E12: 951
A13: California | B13: 12618740 | C13: 3743642 | D13: 3741168 | E13: 2474
A14: Colorado | B14: 1249008 | C14: 386765 | D14: 379757 | E14: 7008
A15: Connecticut | B15: 954542 | C15: 267800 | D15: 243656 | E15: 24144
A16: Delaware | B16: 218971 | C16: 62762 | D16: 9817 | E16: 52945
A17: Dist. Of Col. | B17: 261139 | C17: 107983 | D17: 66488 | E17: 41495
A18: Florida | B18: 3659143 | C18: N/A | D18: N/A | E18: N/A
A19: Georgia | B19: 1957134 | C19: N/A | D19: N/A | E19: N/A
A20: Guam | B20: 35908 | C20: 4208 | D20: N/A | E20: 4208
A21: Hawaii | B21: 312149 | C21: 111530 | D21: 20366 | E21: 91164
A22: Idaho | B22: 294796 | C22: N/A | D22: N/A | E22: N/A
A23: Illinois | B23: 2619375 | C23: 670127 | D23: 562511 | E23: 107616
A24: Indiana | B24: 1310771 | C24: 310202 | D24: 310202 | E24: 0
A25: Iowa | B25: 603260 | C25: 171270 | D25: 156133 | E25: 15137
A26: Kansas | B26: 363294 | C26: N/A | D26: N/A | E26: N/A
A27: Kentucky | B27: 1294481 | C27: 450936 | D27: 450936 | E27: 0
A28: Louisiana | B28: 1673188 | C28: 507668 | D28: 507668 | E28: 0
A29: Maine | B29: 261086 | C29: 12210 | D29: 12210 | E29: 0
A30: Maryland | B30: 1222071 | C30: 310968 | D30: 310968 | E30: 0
A31: Massachusetts | B31: 1488230 | C31: 336784 | D31: 0 | E31: 336784
A32: Michigan | B32: 2435356 | C32: 698135 | D32: 645972 | E32: 52163
A33: Minnesota | B33: 1043848 | C33: 187912 | D33: 186981 | E33: 931
A34: Mississippi | B34: 674239 | C34: N/A | D34: N/A | E34: N/A
A35: Missouri | B35: 881755 | C35: N/A | D35: N/A | E35: N/A
A36: Montana | B36: 255239 | C36: 98136 | D36: 98136 | E36: 0
A37: N. Mariana Islands | B37: 16109 | C37: N/A | D37: N/A | E37: N/A
A38: Nebraska | B38: 245217 | C38: N/A | D38: N/A | E38: N/A
A39: Nevada | B39: 587603 | C39: 209747 | D39: 209747 | E39: 0
A40: New Hampshire | B40: 184346 | C40: 54127 | D40: 53842 | E40: 285
A41: New Jersey | B41: 1631808 | C41: 541972 | D41: 541972 | E41: 0
A42: New Mexico | B42: 831563 | C42: 254692 | D42: 254692 | E42: 0
...

Sheet April-2019
A1: Total Medicaid Enrollees - VIII Group Break Out Report
A2: April-2019
A3: Updated February 2020
A4: Reported on the CMS-64
A7: State | B7: Total Medicaid Enrollees | C7: Total VIII Group Enrollees | D7: Total VIII Group Newly Eligible Enrollees | E7: Total VIII Group Not Newly Eligible Enrollees
A8: Alabama | B8: 1030917 | C8: N/A | D8: N/A | E8: N/A
A9: Alaska | B9: 206677 | C9: 51144 | D9: 51130 | E9: 14
A10: Amer. Samoa * | B10: 37829 | C10: N/A | D10: N/A | E10: N/A
A11: Arizona | B11: 1876550 | C11: 427072 | D11: 107443 | E11: 319629
A12: Arkansas | B12: 829466 | C12: 250832 | D12: 249912 | E12: 920
A13: California | B13: 12693315 | C13: 3768859 | D13: 3762176 | E13: 6683
A14: Colorado | B14: 1235646 | C14: 378962 | D14: 371819 | E14: 7143
A15: Connecticut | B15: 950722 | C15: 266719 | D15: 242640 | E15: 24079
A16: Delaware | B16: 218611 | C16: 62534 | D16: 9593 | E16: 52941
A17: Dist. Of Col. | B17: 260916 | C17: 107772 | D17: 66510 | E17: 41262
A18: Florida | B18: 3813445 | C18: N/A | D18: N/A | E18: N/A
A19: Georgia | B19: 1960778 | C19: N/A | D19: N/A | E19: N/A
A20: Guam | B20: 35865 | C20: 4216 | D20: N/A | E20: 4216
A21: Hawaii | B21: 310597 | C21: 110678 | D21: 20114 | E21: 90564
A22: Idaho | B22: 297787 | C22: N/A | D22: N/A | E22: N/A
A23: Illinois | B23: 2611653 | C23: 669227 | D23: 561633 | E23: 107594
A24: Indiana | B24: 1336106 | C24: 313191 | D24: 313191 | E24: 0
A25: Iowa | B25: 606174 | C25: 172153 | D25: 157036 | E25: 15117
A26: Kansas | B26: 354789 | C26: N/A | D26: N/A | E26: N/A
A27: Kentucky | B27: 1288626 | C27: 449500 | D27: 449500 | E27: 0
A28: Louisiana | B28: 1633613 | C28: 478930 | D28: 478930 | E28: 0
A29: Maine | B29: 262988 | C29: 19812 | D29: 15399 | E29: 4413
A30: Maryland | B30: 1224567 | C30: 309844 | D30: 309844 | E30: 0
A31: Massachusetts | B31: 1442299 | C31: 334027 | D31: 0 | E31: 334027
A32: Michigan | B32: 2419259 | C32: 690711 | D32: 639880 | E32: 50831
A33: Minnesota | B33: 1073560 | C33: 193826 | D33: 193000 | E33: 826
A34: Mississippi | B34: 674544 | C34: N/A | D34: N/A | E34: N/A
A35: Missouri | B35: 870719 | C35: N/A | D35: N/A | E35: N/A
A36: Montana | B36: 257505 | C36: 98741 | D36: 98741 | E36: 0
A37: N. Mariana Islands | B37: 16229 | C37: N/A | D37: N/A | E37: N/A
A38: Nebraska | B38: 245121 | C38: N/A | D38: N/A | E38: N/A
A39: Nevada | B39: 589216 | C39: 210608 | D39: 210608 | E39: 0
A40: New Hampshire | B40: 183038 | C40: 53424 | D40: 53138 | E40: 286
A41: New Jersey | B41: 1620134 | C41: 537233 | D41: 537233 | E41: 0
A42: New Mexico | B42: 834204 | C42: 258061 | D42: 258061 | E42: 0
...

Sheet May-2019
A1: Total Medicaid Enrollees - VIII Group Break Out Report
A2: May-2019
A3: Updated February 2020
A4: Reported on the CMS-64
A7: State | B7: Total Medicaid Enrollees | C7: Total VIII Group Enrollees | D7: Total VIII Group Newly Eligible Enrollees | E7: Total VIII Group Not Newly Eligible Enrollees
A8: Alabama | B8: 1033498 | C8: N/A | D8: N/A | E8: N/A
A9: Alaska | B9: 206036 | C9: 51347 | D9: 51330 | E9: 17
A10: Amer. Samoa * | B10: 37829 | C10: N/A | D10: N/A | E10: N/A
A11: Arizona | B11: 1871082 | C11: 425811 | D11: 107086 | E11: 318725
A12: Arkansas | B12: 822617 | C12: 249308 | D12: 248377 | E12: 931
A13: California | B13: 12611814 | C13: 3741920 | D13: 3732198 | E13: 9722
A14: Colorado | B14: 1235211 | C14: 379544 | D14: 372306 | E14: 7238
A15: Connecticut | B15: 955463 | C15: 267707 | D15: 243615 | E15: 24092
A16: Delaware | B16: 218326 | C16: 62429 | D16: 9542 | E16: 52887
A17: Dist. Of Col. | B17: 260350 | C17: 107478 | D17: 66313 | E17: 41165
A18: Florida | B18: 3800560 | C18: N/A | D18: N/A | E18: N/A
A19: Georgia | B19: 1965793 | C19: N/A | D19: N/A | E19: N/A
A20: Guam | B20: 35692 | C20: 4193 | D20: N/A | E20: 4193
A21: Hawaii | B21: 308739 | C21: 110089 | D21: 19919 | E21: 90170
A22: Idaho | B22: 298643 | C22: N/A | D22: N/A | E22: N/A
A23: Illinois | B23: 2592841 | C23: 661292 | D23: 553675 | E23: 107617
A24: Indiana | B24: 1323990 | C24: 313049 | D24: 313049 | E24: 0
A25: Iowa | B25: 605338 | C25: 172015 | D25: 157117 | E25: 14898
A26: Kansas | B26: 350174 | C26: N/A | D26: N/A | E26: N/A
A27: Kentucky | B27: 1290594 | C27: 450702 | D27: 450702 | E27: 0
A28: Louisiana | B28: 1618198 | C28: 468309 | D28: 468309 | E28: 0
A29: Maine | B29: 268056 | C29: 24824 | D29: 18981 | E29: 5843
A30: Maryland | B30: 1227887 | C30: 310074 | D30: 310074 | E30: 0
A31: Massachusetts | B31: 1452226 | C31: 335973 | D31: 0 | E31: 335973
A32: Michigan | B32: 2402672 | C32: 680631 | D32: 632048 | E32: 48583
A33: Minnesota | B33: 1060628 | C33: 190089 | D33: 189186 | E33: 903
A34: Mississippi | B34: 674961 | C34: N/A | D34: N/A | E34: N/A
A35: Missouri | B35: 858822 | C35: N/A | D35: N/A | E35: N/A
A36: Montana | B36: 255804 | C36: 97544 | D36: 97544 | E36: 0
A37: N. Mariana Islands | B37: 16446 | C37: N/A | D37: N/A | E37: N/A
A38: Nebraska | B38: 243894 | C38: N/A | D38: N/A | E38: N/A
A39: Nevada | B39: 588394 | C39: 210158 | D39: 210158 | E39: 0
A40: New Hampshire | B40: 182244 | C40: 52903 | D40: 52622 | E40: 281
A41: New Jersey | B41: 1604005 | C41: 531061 | D41: 531061 | E41: 0
A42: New Mexico | B42: 831546 | C42: 257784 | D42: 257784 | E42: 0
...

Sheet June-2019
A1: Total Medicaid Enrollees - VIII Group Break Out Report
A2: June-2019
A3: Updated February 2020
A4: Reported on the CMS-64
A7: State | B7: Total Medicaid Enrollees | C7: Total VIII Group Enrollees | D7: Total VIII Group Newly Eligible Enrollees | E7: Total VIII Group Not Newly Eligible Enrollees
A8: Alabama | B8: 1035250 | C8: N/A | D8: N/A | E8: N/A
A9: Alaska | B9: 204493 | C9: 51172 | D9: 51157 | E9: 15
A10: Amer. Samoa * | B10: 37829 | C10: N/A | D10: N/A | E10: N/A
A11: Arizona | B11: 1861477 | C11: 423482 | D11: 105668 | E11: 317814
A12: Arkansas | B12: 825397 | C12: 250431 | D12: 249523 | E12: 908
A13: California | B13: 12437994 | C13: 3696925 | D13: 3684894 | E13: 12031
A14: Colorado | B14: 1234143 | C14: 380442 | D14: 373346 | E14: 7096
A15: Connecticut | B15: 952040 | C15: 267885 | D15: 243618 | E15: 24267
A16: Delaware | B16: 177665 | C16: 62488 | D16: 9547 | E16: 52941
A17: Dist. Of Col. | B17: 258517 | C17: 106551 | D17: 65573 | E17: 40978
A18: Florida | B18: 3771711 | C18: N/A | D18: N/A | E18: N/A
A19: Georgia | B19: 1962735 | C19: N/A | D19: N/A | E19: N/A
A20: Guam | B20: 35499 | C20: 4171 | D20: N/A | E20: 4171
A21: Hawaii | B21: 301359 | C21: 107314 | D21: 19235 | E21: 88079
A22: Idaho | B22: 298258 | C22: N/A | D22: N/A | E22: N/A
A23: Illinois | B23: 2566110 | C23: 655276 | D23: 547918 | E23: 107358
A24: Indiana | B24: 1307223 | C24: 309510 | D24: 309510 | E24: 0
A25: Iowa | B25: 604790 | C25: 172180 | D25: 157341 | E25: 14839
A26: Kansas | B26: 341484 | C26: N/A | D26: N/A | E26: N/A
A27: Kentucky | B27: 1289799 | C27: 450707 | D27: 450707 | E27: 0
A28: Louisiana | B28: 1577893 | C28: 460757 | D28: 460757 | E28: 0
A29: Maine | B29: 270006 | C29: 28462 | D29: 21514 | E29: 6948
A30: Maryland | B30: 1229390 | C30: 310031 | D30: 310031 | E30: 0
A31: Massachusetts | B31: 1455990 | C31: 336735 | D31: 0 | E31: 336735
A32: Michigan | B32: 2385506 | C32: 671648 | D32: 625194 | E32: 46454
A33: Minnesota | B33: 1040633 | C33: 185011 | D33: 184151 | E33: 860
A34: Mississippi | B34: 673247 | C34: N/A | D34: N/A | E34: N/A
A35: Missouri | B35: 847272 | C35: N/A | D35: N/A | E35: N/A
A36: Montana | B36: 252830 | C36: 95805 | D36: 95805 | E36: 0
A37: N. Mariana Islands | B37: 16336 | C37: N/A | D37: N/A | E37: N/A
A38: Nebraska | B38: 241856 | C38: N/A | D38: N/A | E38: N/A
A39: Nevada | B39: 586808 | C39: 209695 | D39: 209695 | E39: 0
A40: New Hampshire | B40: 180873 | C40: 52421 | D40: 52137 | E40: 284
A41: New Jersey | B41: 1570169 | C41: 518216 | D41: 518216 | E41: 0
A42: New Mexico | B42: 825498 | C42: 256424 | D42: 256424 | E42: 0
...

Sheet July-2019
A1: Total Medicaid Enrollees - VIII Group Break Out Report
A2: July-2019
A3: Updated January 2021
A4: Reported on the CMS-64
A7: State | B7: Total Medicaid Enrollees | C7: Total VIII Group Enrollees | D7: Total VIII Group Newly Eligible Enrollees | E7: Total VIII Group Not Newly Eligible Enrollees
A8: Alabama | B8: 1039621 | C8: N/A | D8: N/A | E8: N/A
A9: Alaska | B9: 212689 | C9: 52827 | D9: 52825 | E9: 2
A10: Amer. Samoa | B10: 37829 | C10: N/A | D10: N/A | E10: N/A
A11: Arizona | B11: 1878446 | C11: 426398 | D11: 106815 | E11: 319583
A12: Arkansas | B12: 828694 | C12: 251909 | D12: 250980 | E12: 929
A13: California | B13: 12617496 | C13: 3748234 | D13: 3733554 | E13: 14680
A14: Colorado | B14: 1231471 | C14: 375957 | D14: 367859 | E14: 8098
A15: Connecticut | B15: 949434 | C15: 266955 | D15: 242723 | E15: 24232
A16: Delaware | B16: 214927 | C16: 63148 | D16: 9611 | E16: 53537
A17: Dist. Of Col. | B17: 263389 | C17: 109273 | D17: 67157 | E17: 42116
A18: Florida | B18: 3814296 | C18: N/A | D18: N/A | E18: N/A
A19: Georgia | B19: 1892562 | C19: N/A | D19: N/A | E19: N/A
A20: Guam | B20: 35524 | C20: 4166 | D20: N/A | E20: 4166
A21: Hawaii | B21: 310785 | C21: 110424 | D21: 19886 | E21: 90538
A22: Idaho | B22: 290902 | C22: 0 | D22: 0 | E22: 0
A23: Illinois | B23: 2680627 | C23: 685985 | D23: 577871 | E23: 108114
A24: Indiana | B24: 1336196 | C24: 310882 | D24: 310882 | E24: 0
A25: Iowa | B25: 605053 | C25: 172682 | D25: 157709 | E25: 14973
A26: Kansas | B26: 358081 | C26: N/A | D26: N/A | E26: N/A
A27: Kentucky | B27: 1288398 | C27: 451066 | D27: 451066 | E27: 0
A28: Louisiana | B28: 1610710 | C28: 467469 | D28: 467469 | E28: 0
A29: Maine | B29: 274242 | C29: 33001 | D29: 24837 | E29: 8164
A30: Maryland | B30: 1233962 | C30: 311534 | D30: 311534 | E30: 0
A31: Massachusetts | B31: 1731120 | C31: 342411 | D31: 0 | E31: 342411
A32: Michigan | B32: 2373597 | C32: 665811 | D32: 609473 | E32: 56338
A33: Minnesota | B33: 1071241 | C33: 191341 | D33: 190616 | E33: 725
A34: Mississippi | B34: 672198 | C34: N/A | D34: N/A | E34: N/A
A35: Missouri | B35: 839308 | C35: N/A | D35: N/A | E35: N/A
A36: Montana | B36: 253496 | C36: 95867 | D36: 95867 | E36: 0
A37: N. Mariana Islands | B37: 16559 | C37: N/A | D37: N/A | E37: N/A
A38: Nebraska | B38: 243927 | C38: N/A | D38: N/A | E38: N/A
A39: Nevada | B39: 588274 | C39: 210386 | D39: 210386 | E39: 0
A40: New Hampshire | B40: 180340 | C40: 51844 | D40: 51567 | E40: 277
A41: New Jersey | B41: 1618646 | C41: 533146 | D41: 533146 | E41: 0
A42: New Mexico | B42: 829459 | C42: 257816 | D42: 257816 | E42: 0
...

Sheet August-2019
A1: Total Medicaid Enrollees - VIII Group Break Out Report
A2: August-2019
A3: Updated January 2021
A4: Reported on the CMS-64
A7: State | B7: Total Medicaid Enrollees | C7: Total VIII Group Enrollees | D7: Total VIII Group Newly Eligible Enrollees | E7: Total VIII Group Not Newly Eligible Enrollees
A8: Alabama | B8: 1043767 | C8: N/A | D8: N/A | E8: N/A
A9: Alaska | B9: 213643 | C9: 53123 | D9: 53120 | E9: 3
A10: Amer. Samoa | B10: 37829 | C10: N/A | D10: N/A | E10: N/A
A11: Arizona | B11: 1888238 | C11: 430695 | D11: 107682 | E11: 323013
A12: Arkansas | B12: 830083 | C12: 253168 | D12: 252201 | E12: 967
A13: California | B13: 12593368 | C13: 3738516 | D13: 3722449 | E13: 16067
A14: Colorado | B14: 1230388 | C14: 378037 | D14: 370211 | E14: 7826
A15: Connecticut | B15: 952410 | C15: 268041 | D15: 243708 | E15: 24333
A16: Delaware | B16: 213738 | C16: 62546 | D16: 9515 | E16: 53031
A17: Dist. Of Col. | B17: 263605 | C17: 108784 | D17: 66837 | E17: 41947
A18: Florida | B18: 3800726 | C18: N/A | D18: N/A | E18: N/A
A19: Georgia | B19: 2027915 | C19: N/A | D19: N/A | E19: N/A
A20: Guam | B20: 35385 | C20: 4168 | D20: N/A | E20: 4168
A21: Hawaii | B21: 310623 | C21: 110223 | D21: 19872 | E21: 90351
A22: Idaho | B22: 285233 | C22: 0 | D22: 0 | E22: 0
A23: Illinois | B23: 2682054 | C23: 687746 | D23: 579871 | E23: 107875
A24: Indiana | B24: 1327863 | C24: 309264 | D24: 309264 | E24: 0
A25: Iowa | B25: 604398 | C25: 173062 | D25: 157854 | E25: 15208
A26: Kansas | B26: 359056 | C26: N/A | D26: N/A | E26: N/A
A27: Kentucky | B27: 1288645 | C27: 451480 | D27: 451480 | E27: 0
A28: Louisiana | B28: 1618143 | C28: 470125 | D28: 470125 | E28: 0
A29: Maine | B29: 277568 | C29: 38458 | D29: 28665 | E29: 9793
A30: Maryland | B30: 1239877 | C30: 312759 | D30: 312759 | E30: 0
A31: Massachusetts | B31: 1736721 | C31: 352927 | D31: 0 | E31: 352927
A32: Michigan | B32: 2374059 | C32: 662823 | D32: 609142 | E32: 53681
A33: Minnesota | B33: 1060208 | C33: 188113 | D33: 187320 | E33: 793
A34: Mississippi | B34: 672824 | C34: N/A | D34: N/A | E34: N/A
A35: Missouri | B35: 838406 | C35: N/A | D35: N/A | E35: N/A
A36: Montana | B36: 252012 | C36: 94674 | D36: 94674 | E36: 0
A37: N. Mariana Islands | B37: 16620 | C37: N/A | D37: N/A | E37: N/A
A38: Nebraska | B38: 237329 | C38: N/A | D38: N/A | E38: N/A
A39: Nevada | B39: 588123 | C39: 210184 | D39: 210184 | E39: 0
A40: New Hampshire | B40: 180680 | C40: 51773 | D40: 51491 | E40: 282
A41: New Jersey | B41: 1611421 | C41: 530959 | D41: 530959 | E41: 0
A42: New Mexico | B42: 829406 | C42: 258239 | D42: 258239 | E42: 0
...

Sheet September-2019
A1: Total Medicaid Enrollees - VIII Group Break Out Report
A2: September-2019
A3: Updated January 2021
A4: Reported on the CMS-64
A7: State | B7: Total Medicaid Enrollees | C7: Total VIII Group Enrollees | D7: Total VIII Group Newly Eligible Enrollees | E7: Total VIII Group Not Newly Eligible Enrollees
A8: Alabama | B8: 1046192 | C8: N/A | D8: N/A | E8: N/A
A9: Alaska | B9: 213560 | C9: 53172 | D9: 53169 | E9: 3
A10: Amer. Samoa | B10: 37829 | C10: N/A | D10: N/A | E10: N/A
A11: Arizona | B11: 1892992 | C11: 432744 | D11: 107328 | E11: 325416
A12: Arkansas | B12: 831542 | C12: 254212 | D12: 253286 | E12: 926
